#!/usr/bin/env python3
"""
Test suite for error recovery functionality
"""

import unittest
import asyncio
from unittest.mock import Mock, patch
from src.bucika_gsr_pc.error_recovery import ErrorRecoveryManager, ServiceErrorHandler, ErrorSeverity, RecoveryAction


class TestErrorRecovery(unittest.TestCase):
    """Test error recovery functionality"""
    
    def setUp(self):
        """Set up test environment"""
        self.error_manager = ErrorRecoveryManager()
    
    def test_error_manager_initialization(self):
        """Test error recovery manager initialization"""
        self.assertEqual(self.error_manager.max_retries, 3)
        self.assertEqual(self.error_manager.escalation_threshold, 5)
        self.assertFalse(self.error_manager.running)
        self.assertEqual(len(self.error_manager.error_patterns), 0)
    
    def test_service_error_handler_creation(self):
        """Test service error handler creation"""
        handler = ServiceErrorHandler("test_service", self.error_manager)
        
        self.assertEqual(handler.service_name, "test_service")
        self.assertEqual(handler.error_recovery_manager, self.error_manager)
        self.assertIsNone(handler.restart_callback)
        self.assertIsNone(handler.reset_callback)
    
    def test_error_severity_classification(self):
        """Test automatic error severity classification"""
        # Test different types of errors
        connection_error = ConnectionError("Network connection failed")
        runtime_error = RuntimeError("Unexpected runtime error")
        value_error = ValueError("Invalid parameter value")
        
        # Note: The actual classification logic would be in the error manager
        # This is a basic test to verify the concept
        self.assertIsInstance(connection_error, Exception)
        self.assertIsInstance(runtime_error, Exception)
        self.assertIsInstance(value_error, Exception)
    
    def test_error_callback_registration(self):
        """Test error callback registration"""
        callback_called = False
        
        def test_callback(service_name: str, error: Exception) -> bool:
            nonlocal callback_called
            callback_called = True
            return True
        
        self.error_manager.register_error_callback("test_service", test_callback)
        
        # Verify callback is registered
        self.assertIn("test_service", self.error_manager.service_callbacks)
    
    def test_recovery_action_determination(self):
        """Test recovery action determination based on error type"""
        # Test different recovery actions
        self.assertIsInstance(RecoveryAction.RETRY, RecoveryAction)
        self.assertIsInstance(RecoveryAction.RESTART, RecoveryAction)
        self.assertIsInstance(RecoveryAction.RECONNECT, RecoveryAction)
        self.assertIsInstance(RecoveryAction.RESET_STATE, RecoveryAction)
        self.assertIsInstance(RecoveryAction.ESCALATE, RecoveryAction)
    
    def test_error_pattern_learning(self):
        """Test error pattern learning capability"""
        # This would test the ML-based pattern recognition
        # For now, just verify the concept exists
        initial_patterns = len(self.error_manager.error_patterns)
        
        # After processing some errors, patterns should be learned
        # (This would require actual error processing implementation)
        self.assertIsInstance(self.error_manager.error_patterns, dict)
    
    def test_escalation_procedures(self):
        """Test error escalation procedures"""
        # Test that escalation threshold is respected
        self.assertGreater(self.error_manager.escalation_threshold, 0)
        
        # Test escalation tracking
        self.assertIsInstance(self.error_manager.stats, dict)
        self.assertIn('total_errors', self.error_manager.stats)
        self.assertIn('recovery_rate', self.error_manager.stats)
    
    def test_error_recovery_stats(self):
        """Test error recovery statistics tracking"""
        stats = self.error_manager.get_error_report()
        
        self.assertIsInstance(stats, dict)
        self.assertIn('total_errors', stats)
        self.assertIn('recovery_rate', stats)
        self.assertIn('service_errors', stats)
        self.assertIn('recent_errors', stats)
    
    @patch('asyncio.create_task')
    def test_async_error_handling(self, mock_create_task):
        """Test asynchronous error handling"""
        async def mock_error_handler():
            return True
        
        # Test that async error handling can be initiated
        # This would test the actual async error processing
        self.assertTrue(callable(mock_error_handler))
    
    def test_service_restart_capability(self):
        """Test service restart capability"""
        restart_called = False
        
        async def mock_restart():
            nonlocal restart_called
            restart_called = True
            return True
        
        handler = ServiceErrorHandler("test_service", self.error_manager)
        handler.set_restart_callback(mock_restart)
        
        self.assertIsNotNone(handler.restart_callback)
    
    def test_state_reset_capability(self):
        """Test service state reset capability"""
        reset_called = False
        
        async def mock_reset():
            nonlocal reset_called
            reset_called = True
            return True
        
        handler = ServiceErrorHandler("test_service", self.error_manager)
        handler.set_reset_callback(mock_reset)
        
        self.assertIsNotNone(handler.reset_callback)


if __name__ == '__main__':
    unittest.main()